{
 "cells": [
  {
   "cell_type": "code",
   "execution_count": null,
   "metadata": {},
   "outputs": [],
   "source": [
    "pip install --upgrade pip"
   ]
  },
  {
   "cell_type": "code",
   "execution_count": null,
   "metadata": {},
   "outputs": [],
   "source": [
    "pip install tensorflow"
   ]
  },
  {
   "cell_type": "code",
   "execution_count": 13,
   "metadata": {},
   "outputs": [
    {
     "ename": "ImportError",
     "evalue": "Traceback (most recent call last):\n  File \"C:\\Users\\bulka\\AppData\\Roaming\\Python\\Python37\\site-packages\\tensorflow\\python\\pywrap_tensorflow.py\", line 64, in <module>\n    from tensorflow.python._pywrap_tensorflow_internal import *\nImportError: DLL load failed: Nie można odnaleźć określonego modułu.\n\n\nFailed to load the native TensorFlow runtime.\n\nSee https://www.tensorflow.org/install/errors\n\nfor some common reasons and solutions.  Include the entire stack trace\nabove this error message when asking for help.",
     "output_type": "error",
     "traceback": [
      "\u001b[1;31m---------------------------------------------------------------------------\u001b[0m",
      "\u001b[1;31mImportError\u001b[0m                               Traceback (most recent call last)",
      "\u001b[1;32m~\\AppData\\Roaming\\Python\\Python37\\site-packages\\tensorflow\\python\\pywrap_tensorflow.py\u001b[0m in \u001b[0;36m<module>\u001b[1;34m\u001b[0m\n\u001b[0;32m     63\u001b[0m   \u001b[1;32mtry\u001b[0m\u001b[1;33m:\u001b[0m\u001b[1;33m\u001b[0m\u001b[1;33m\u001b[0m\u001b[0m\n\u001b[1;32m---> 64\u001b[1;33m     \u001b[1;32mfrom\u001b[0m \u001b[0mtensorflow\u001b[0m\u001b[1;33m.\u001b[0m\u001b[0mpython\u001b[0m\u001b[1;33m.\u001b[0m\u001b[0m_pywrap_tensorflow_internal\u001b[0m \u001b[1;32mimport\u001b[0m \u001b[1;33m*\u001b[0m\u001b[1;33m\u001b[0m\u001b[1;33m\u001b[0m\u001b[0m\n\u001b[0m\u001b[0;32m     65\u001b[0m   \u001b[1;31m# This try catch logic is because there is no bazel equivalent for py_extension.\u001b[0m\u001b[1;33m\u001b[0m\u001b[1;33m\u001b[0m\u001b[1;33m\u001b[0m\u001b[0m\n",
      "\u001b[1;31mImportError\u001b[0m: DLL load failed: Nie można odnaleźć określonego modułu.",
      "\nDuring handling of the above exception, another exception occurred:\n",
      "\u001b[1;31mImportError\u001b[0m                               Traceback (most recent call last)",
      "\u001b[1;32m<ipython-input-13-64156d691fe5>\u001b[0m in \u001b[0;36m<module>\u001b[1;34m\u001b[0m\n\u001b[1;32m----> 1\u001b[1;33m \u001b[1;32mimport\u001b[0m \u001b[0mtensorflow\u001b[0m \u001b[1;32mas\u001b[0m \u001b[0mtf\u001b[0m\u001b[1;33m\u001b[0m\u001b[1;33m\u001b[0m\u001b[0m\n\u001b[0m",
      "\u001b[1;32m~\\AppData\\Roaming\\Python\\Python37\\site-packages\\tensorflow\\__init__.py\u001b[0m in \u001b[0;36m<module>\u001b[1;34m\u001b[0m\n\u001b[0;32m     39\u001b[0m \u001b[1;32mimport\u001b[0m \u001b[0msys\u001b[0m \u001b[1;32mas\u001b[0m \u001b[0m_sys\u001b[0m\u001b[1;33m\u001b[0m\u001b[1;33m\u001b[0m\u001b[0m\n\u001b[0;32m     40\u001b[0m \u001b[1;33m\u001b[0m\u001b[0m\n\u001b[1;32m---> 41\u001b[1;33m \u001b[1;32mfrom\u001b[0m \u001b[0mtensorflow\u001b[0m\u001b[1;33m.\u001b[0m\u001b[0mpython\u001b[0m\u001b[1;33m.\u001b[0m\u001b[0mtools\u001b[0m \u001b[1;32mimport\u001b[0m \u001b[0mmodule_util\u001b[0m \u001b[1;32mas\u001b[0m \u001b[0m_module_util\u001b[0m\u001b[1;33m\u001b[0m\u001b[1;33m\u001b[0m\u001b[0m\n\u001b[0m\u001b[0;32m     42\u001b[0m \u001b[1;32mfrom\u001b[0m \u001b[0mtensorflow\u001b[0m\u001b[1;33m.\u001b[0m\u001b[0mpython\u001b[0m\u001b[1;33m.\u001b[0m\u001b[0mutil\u001b[0m\u001b[1;33m.\u001b[0m\u001b[0mlazy_loader\u001b[0m \u001b[1;32mimport\u001b[0m \u001b[0mLazyLoader\u001b[0m \u001b[1;32mas\u001b[0m \u001b[0m_LazyLoader\u001b[0m\u001b[1;33m\u001b[0m\u001b[1;33m\u001b[0m\u001b[0m\n\u001b[0;32m     43\u001b[0m \u001b[1;33m\u001b[0m\u001b[0m\n",
      "\u001b[1;32m~\\AppData\\Roaming\\Python\\Python37\\site-packages\\tensorflow\\python\\__init__.py\u001b[0m in \u001b[0;36m<module>\u001b[1;34m\u001b[0m\n\u001b[0;32m     38\u001b[0m \u001b[1;31m# pylint: disable=wildcard-import,g-bad-import-order,g-import-not-at-top\u001b[0m\u001b[1;33m\u001b[0m\u001b[1;33m\u001b[0m\u001b[1;33m\u001b[0m\u001b[0m\n\u001b[0;32m     39\u001b[0m \u001b[1;33m\u001b[0m\u001b[0m\n\u001b[1;32m---> 40\u001b[1;33m \u001b[1;32mfrom\u001b[0m \u001b[0mtensorflow\u001b[0m\u001b[1;33m.\u001b[0m\u001b[0mpython\u001b[0m\u001b[1;33m.\u001b[0m\u001b[0meager\u001b[0m \u001b[1;32mimport\u001b[0m \u001b[0mcontext\u001b[0m\u001b[1;33m\u001b[0m\u001b[1;33m\u001b[0m\u001b[0m\n\u001b[0m\u001b[0;32m     41\u001b[0m \u001b[1;33m\u001b[0m\u001b[0m\n\u001b[0;32m     42\u001b[0m \u001b[1;31m# pylint: enable=wildcard-import\u001b[0m\u001b[1;33m\u001b[0m\u001b[1;33m\u001b[0m\u001b[1;33m\u001b[0m\u001b[0m\n",
      "\u001b[1;32m~\\AppData\\Roaming\\Python\\Python37\\site-packages\\tensorflow\\python\\eager\\context.py\u001b[0m in \u001b[0;36m<module>\u001b[1;34m\u001b[0m\n\u001b[0;32m     33\u001b[0m \u001b[1;32mfrom\u001b[0m \u001b[0mtensorflow\u001b[0m\u001b[1;33m.\u001b[0m\u001b[0mcore\u001b[0m\u001b[1;33m.\u001b[0m\u001b[0mprotobuf\u001b[0m \u001b[1;32mimport\u001b[0m \u001b[0mconfig_pb2\u001b[0m\u001b[1;33m\u001b[0m\u001b[1;33m\u001b[0m\u001b[0m\n\u001b[0;32m     34\u001b[0m \u001b[1;32mfrom\u001b[0m \u001b[0mtensorflow\u001b[0m\u001b[1;33m.\u001b[0m\u001b[0mcore\u001b[0m\u001b[1;33m.\u001b[0m\u001b[0mprotobuf\u001b[0m \u001b[1;32mimport\u001b[0m \u001b[0mrewriter_config_pb2\u001b[0m\u001b[1;33m\u001b[0m\u001b[1;33m\u001b[0m\u001b[0m\n\u001b[1;32m---> 35\u001b[1;33m \u001b[1;32mfrom\u001b[0m \u001b[0mtensorflow\u001b[0m\u001b[1;33m.\u001b[0m\u001b[0mpython\u001b[0m \u001b[1;32mimport\u001b[0m \u001b[0mpywrap_tfe\u001b[0m\u001b[1;33m\u001b[0m\u001b[1;33m\u001b[0m\u001b[0m\n\u001b[0m\u001b[0;32m     36\u001b[0m \u001b[1;32mfrom\u001b[0m \u001b[0mtensorflow\u001b[0m\u001b[1;33m.\u001b[0m\u001b[0mpython\u001b[0m \u001b[1;32mimport\u001b[0m \u001b[0mtf2\u001b[0m\u001b[1;33m\u001b[0m\u001b[1;33m\u001b[0m\u001b[0m\n\u001b[0;32m     37\u001b[0m \u001b[1;32mfrom\u001b[0m \u001b[0mtensorflow\u001b[0m\u001b[1;33m.\u001b[0m\u001b[0mpython\u001b[0m\u001b[1;33m.\u001b[0m\u001b[0mclient\u001b[0m \u001b[1;32mimport\u001b[0m \u001b[0mpywrap_tf_session\u001b[0m\u001b[1;33m\u001b[0m\u001b[1;33m\u001b[0m\u001b[0m\n",
      "\u001b[1;32m~\\AppData\\Roaming\\Python\\Python37\\site-packages\\tensorflow\\python\\pywrap_tfe.py\u001b[0m in \u001b[0;36m<module>\u001b[1;34m\u001b[0m\n\u001b[0;32m     26\u001b[0m \u001b[1;33m\u001b[0m\u001b[0m\n\u001b[0;32m     27\u001b[0m \u001b[1;31m# pylint: disable=invalid-import-order,g-bad-import-order, wildcard-import, unused-import\u001b[0m\u001b[1;33m\u001b[0m\u001b[1;33m\u001b[0m\u001b[1;33m\u001b[0m\u001b[0m\n\u001b[1;32m---> 28\u001b[1;33m \u001b[1;32mfrom\u001b[0m \u001b[0mtensorflow\u001b[0m\u001b[1;33m.\u001b[0m\u001b[0mpython\u001b[0m \u001b[1;32mimport\u001b[0m \u001b[0mpywrap_tensorflow\u001b[0m\u001b[1;33m\u001b[0m\u001b[1;33m\u001b[0m\u001b[0m\n\u001b[0m\u001b[0;32m     29\u001b[0m \u001b[1;32mfrom\u001b[0m \u001b[0mtensorflow\u001b[0m\u001b[1;33m.\u001b[0m\u001b[0mpython\u001b[0m\u001b[1;33m.\u001b[0m\u001b[0m_pywrap_tfe\u001b[0m \u001b[1;32mimport\u001b[0m \u001b[1;33m*\u001b[0m\u001b[1;33m\u001b[0m\u001b[1;33m\u001b[0m\u001b[0m\n",
      "\u001b[1;32m~\\AppData\\Roaming\\Python\\Python37\\site-packages\\tensorflow\\python\\pywrap_tensorflow.py\u001b[0m in \u001b[0;36m<module>\u001b[1;34m\u001b[0m\n\u001b[0;32m     81\u001b[0m \u001b[1;32mfor\u001b[0m \u001b[0msome\u001b[0m \u001b[0mcommon\u001b[0m \u001b[0mreasons\u001b[0m \u001b[1;32mand\u001b[0m \u001b[0msolutions\u001b[0m\u001b[1;33m.\u001b[0m  \u001b[0mInclude\u001b[0m \u001b[0mthe\u001b[0m \u001b[0mentire\u001b[0m \u001b[0mstack\u001b[0m \u001b[0mtrace\u001b[0m\u001b[1;33m\u001b[0m\u001b[1;33m\u001b[0m\u001b[0m\n\u001b[0;32m     82\u001b[0m above this error message when asking for help.\"\"\" % traceback.format_exc()\n\u001b[1;32m---> 83\u001b[1;33m   \u001b[1;32mraise\u001b[0m \u001b[0mImportError\u001b[0m\u001b[1;33m(\u001b[0m\u001b[0mmsg\u001b[0m\u001b[1;33m)\u001b[0m\u001b[1;33m\u001b[0m\u001b[1;33m\u001b[0m\u001b[0m\n\u001b[0m\u001b[0;32m     84\u001b[0m \u001b[1;33m\u001b[0m\u001b[0m\n\u001b[0;32m     85\u001b[0m \u001b[1;31m# pylint: enable=wildcard-import,g-import-not-at-top,unused-import,line-too-long\u001b[0m\u001b[1;33m\u001b[0m\u001b[1;33m\u001b[0m\u001b[1;33m\u001b[0m\u001b[0m\n",
      "\u001b[1;31mImportError\u001b[0m: Traceback (most recent call last):\n  File \"C:\\Users\\bulka\\AppData\\Roaming\\Python\\Python37\\site-packages\\tensorflow\\python\\pywrap_tensorflow.py\", line 64, in <module>\n    from tensorflow.python._pywrap_tensorflow_internal import *\nImportError: DLL load failed: Nie można odnaleźć określonego modułu.\n\n\nFailed to load the native TensorFlow runtime.\n\nSee https://www.tensorflow.org/install/errors\n\nfor some common reasons and solutions.  Include the entire stack trace\nabove this error message when asking for help."
     ]
    }
   ],
   "source": [
    "import tensorflow as tf"
   ]
  },
  {
   "cell_type": "code",
   "execution_count": null,
   "metadata": {},
   "outputs": [],
   "source": []
  },
  {
   "cell_type": "code",
   "execution_count": 12,
   "metadata": {},
   "outputs": [
    {
     "name": "stdout",
     "output_type": "stream",
     "text": [
      "Collecting protobuf==3.4.0\n",
      "  Downloading protobuf-3.4.0-py2.py3-none-any.whl (375 kB)\n",
      "Requirement already satisfied: six>=1.9 in c:\\programdata\\anaconda3\\lib\\site-packages (from protobuf==3.4.0) (1.12.0)\n",
      "Requirement already satisfied: setuptools in c:\\users\\bulka\\appdata\\roaming\\python\\python37\\site-packages (from protobuf==3.4.0) (50.3.2)\n",
      "Installing collected packages: protobuf\n",
      "  Attempting uninstall: protobuf\n",
      "    Found existing installation: protobuf 3.6.0\n",
      "    Uninstalling protobuf-3.6.0:\n",
      "      Successfully uninstalled protobuf-3.6.0\n",
      "Successfully installed protobuf-3.4.0\n",
      "Note: you may need to restart the kernel to use updated packages.\n"
     ]
    },
    {
     "name": "stderr",
     "output_type": "stream",
     "text": [
      "ERROR: After October 2020 you may experience errors when installing or updating packages. This is because pip will change the way that it resolves dependency conflicts.\n",
      "\n",
      "We recommend you use --use-feature=2020-resolver to test your packages with the new resolver before it becomes the default.\n",
      "\n",
      "tensorflow 2.3.1 requires protobuf>=3.9.2, but you'll have protobuf 3.4.0 which is incompatible.\n",
      "tensorboard 2.3.0 requires protobuf>=3.6.0, but you'll have protobuf 3.4.0 which is incompatible.\n"
     ]
    }
   ],
   "source": [
    "pip install protobuf==3.4.0"
   ]
  },
  {
   "cell_type": "code",
   "execution_count": 10,
   "metadata": {},
   "outputs": [
    {
     "name": "stdout",
     "output_type": "stream",
     "text": [
      "Name: protobuf\n",
      "Version: 3.6.0\n",
      "Summary: Protocol Buffers\n",
      "Home-page: https://developers.google.com/protocol-buffers/\n",
      "Author: protobuf@googlegroups.com\n",
      "Author-email: protobuf@googlegroups.com\n",
      "License: 3-Clause BSD License\n",
      "Location: c:\\programdata\\anaconda3\\lib\\site-packages\n",
      "Requires: six, setuptools\n",
      "Required-by: tensorflow, tensorboard\n",
      "Note: you may need to restart the kernel to use updated packages.\n"
     ]
    }
   ],
   "source": [
    "pip show protobuf"
   ]
  },
  {
   "cell_type": "code",
   "execution_count": null,
   "metadata": {},
   "outputs": [],
   "source": []
  }
 ],
 "metadata": {
  "kernelspec": {
   "display_name": "Python 3",
   "language": "python",
   "name": "python3"
  },
  "language_info": {
   "codemirror_mode": {
    "name": "ipython",
    "version": 3
   },
   "file_extension": ".py",
   "mimetype": "text/x-python",
   "name": "python",
   "nbconvert_exporter": "python",
   "pygments_lexer": "ipython3",
   "version": "3.7.3"
  }
 },
 "nbformat": 4,
 "nbformat_minor": 2
}
